Tratamento de exceções

As exceções vieram com o PHP 5

O PHP possui um modelo de exceções similar ao de outras linguagens de programação. Uma exceção pode ser lançada (throw) e capturada (catch). Código pode ser envolvido por um bloco try para facilitar a captura de exceções potenciais. Cada bloco try precisa ter ao menos um bloco catch ou finally correspondente.


catch

Múltiplos blocos catch podem ser utilizados para capturar exceções diferentes. A execução normal (quando nenhuma exceção é lançada dentro de um try) irão continuar a execução após o último catch definido em sequência. Exceções podem ser lançadas (ou relançadas) dentro um bloco catch.

Quando uma exceção é lançada o código seguinte não é executado, e o PHP tentará encontrar o primeiro bloco catch coincidente. Se uma exceção não for capturada, um erro PHP fatal será lançado com a mensagem "Uncaught Exception ..." na ausência de uma função definida com set_exception_handler().

A partir do PHP 7.1 um bloco catch pode especificar múltiplas exceções usando o caractere pipe (|). Isto é útil quando diferentes exceções de diferentes hierarquias de classes são tratadas da mesma forma.

finally

A partir do PHP 5.5, um bloco finally pode ser especificado após ou no lugar de blocos catch. Códigos dentro de finally sempre serão executados depois do try ou catch, independente se houve o lançamento de uma exceção, e antes que a execução normal continue.


O objeto lançado precisa ser uma instância da classe Exception ou uma subclasse de Exception. Tentar lançar um objeto sem essa ascendência resultará em um erro fatal.

Exception é a classe base para todas as exceções.

try {
   print "Testar este bloco";
   throw new Exception();
} catch (Exception $e) {
   print "Se algo der errado esta parte será executada!";
} finally {
   print "Esta parte sempre será executada";
}

try {
   try {
      echo 'a-';
      throw new exception();
      echo 'b-';
   } catch (Exception $e) {
      echo 'caught-';
      throw $e;
   } finally {
      echo 'finished-';
   }
} catch (Exception $e) {
   echo 'end-';
}

// a-caught-finished-end-

class MyCustomException extends Exception { }

function exception_handler($exception) {
   echo "Uncaught exception: " , $exception->getMessage(), "\n";
}

set_exception_handler('exception_handler');

try {
   throw new Exception('Uncaught Exception');
} catch (MyCustomException $e) {
   echo "Your custom exception caught ";
   echo $e->getMessage();
} finally {
   echo "I'm always here";
}

print "Not executed";

https://netgen.io/blog/modern-error-handling-in-php

try {
    // run your code here
}
catch (Exception $e) {
    echo $e->getMessage();
}
catch (InvalidArgumentException $e) {
    echo $e->getMessage();
}


<?php
class DivideByZeroException extends Exception {};
class DivideByNegativeException extends Exception {};

function process_divide($denominator)
{
    try
    {
        if ($denominator == 0)
        {
            throw new DivideByZeroException();
        }
        else if ($denominator < 0)
        {
            throw new DivideByNegativeException();
        }
        else
        {
            echo 100 / $denominator;
        }
    }
    catch (DivideByZeroException $ex)
    {
        echo "Divide by zero exception!";
    }
    catch (DivideByNegativeException $ex)
    {
        echo "Divide by negative number exception!";
    }
    catch (Exception $x)
    {
        echo "UNKNOWN EXCEPTION!";
    }
}

process_divide(5);

Mensagem customizada

function dividir($x, $y) {
    if ($y == 0) {
        throw new Exception('Não é possível realizar uma divisão por zero');
    }
    $resultado = $x / $y;
    return $resultado;
};

dividir(10,0);



function dividir($x, $y) {
    if ($y == 0) {
        throw new Exception('é uma divisão por zero.');
    }
    $resultado = $x / $y;
    return $resultado;
};

try {
    echo dividir(5,0)."<br/>";
} catch (Exception $e) {
    echo 'Exceção capturada: ',  $e->getMessage(), "\n";
}


function dividir($x, $y) {
    if ($y == 0) {
        throw new Exception('é uma divisão por zero');
    }
    $resultado = $x / $y;
    return $resultado;
};

try {
    echo dividir(10,2)."<br/>";
    echo dividir(5,0)."<br/>";    
} catch (Exception $e) {
    echo 'Exceção capturada: ',  $e->getMessage(), "\n";
}finally{
    echo "<br> Finalizado.";
}


